<?xml version="1.0" ?>
<robot name="urdf_robot">
  <link name="baseLink">
    <visual>
      <origin rpy="0 0 0" xyz="0 0 0.1"/>
      <geometry>
        <box size="0.01 0.2 0.2"/>
      </geometry>
      <material name="white">
        <color rgba="0.5 0.5 0.5 0.9" />
      </material>
    </visual>
    <collision>
      <origin rpy="0 0 0" xyz="0 0 0.1"/>
      <geometry>
        <box size="0.1 0.2 0.2"/>
      </geometry>
    </collision>
  </link>
   <link name="childA">
    <visual>
      <origin rpy="0 0 0" xyz="0 0 0.1"/>
      <geometry>
        <box size="0.01 0.2 0.2"/>
      </geometry>
      <material name="white">
        <color rgba="0.5 0.5 0.5 0.9" />
      </material>
    </visual>
    <collision>
      <origin rpy="0 0 0" xyz="0 0 0.1"/>
      <geometry>
        <box size="0.01 0.2 0.2"/>
      </geometry>
    </collision>
  </link>
   <joint name="joint_baseLink_childA" type="spherical">
    <parent link="baseLink"/>
    <child link="childA"/>
    <origin xyz="0 0 0"/>
    <axis xyz="1 0 0"/>
  </joint>
   <link name="childB">
    <visual>
      <origin rpy="0 0 0" xyz="0 0 0"/>
      <geometry>
         <box size="2 0.2 0.01"/>
      </geometry>
      <material name="white">
        <color rgba="0.5 0.5 0.5 0.9" />
      </material>
    </visual>
    <collision>
      <origin rpy="0 0 0" xyz="0 0 0"/>
      <geometry>
         <box size="2 0.2 0.01"/>
      </geometry>
    </collision>
  </link>
   <joint name="joint_childA_childB" type="continuous">
    <parent link="childA"/>
    <child link="childB"/>
    <origin xyz="0 0 0.2"/>
    <axis xyz="0 1 0"/>
  </joint>
</robot>