<?xml version="1.0"?>
<robot name="seesaw">
  <link name="base_link">
    <inertial>
      <origin xyz="0 0 0" rpy="0 0 0" />
      <mass value="1" />
      <inertia ixx="0.01336" ixy="0" ixz="0" iyy="0.03416" iyz="0"
          izz="0.016" />
    </inertial>

    <visual>
      <origin xyz="0 0 0.1" rpy="0 0 0" />
      <geometry>
        <box size="0.2 0.01 0.2" />
      </geometry>
      <material name="yellow">
        <color rgba="1.0 0.9 0.0 1.0" />
      </material>
    </visual>

    <collision>
      <origin xyz="0 0 0.1" rpy="0 0 0" />
      <geometry>
        <box size="0.2 0.01 0.2" />
      </geometry>
    </collision>

  </link>

  <link name="board_link">

    <inertial>
      <origin xyz="0 0 0" rpy="0 0 0" />
      <mass value="0.1" />
      <inertia ixx="0.48" ixy="0" ixz="0" iyy="0.01336" iyz="0"
          izz="0.4932" />
    </inertial>

    <visual>
      <origin xyz="0 0 0" rpy="0 0 0" />
      <geometry>
        <box size="0.2 1.2 0.01" />

      </geometry>
      <material name="yellow">
        <color rgba="1.0 0.9 0.0 1.0" />
      </material>
    </visual>

    <collision>
      <origin xyz="0 0 0" rpy="0 0 0" />
      <geometry>
        <box size="0.2 1.2 0.01" />
      </geometry>
    </collision>

  </link>

  <joint name="joint1" type="continuous">
    <parent link="base_link"/>
    <child link="board_link"/>
    <origin xyz="0 0 0.2"/>
    <axis xyz="1 0 0"/>
  </joint>

</robot>